<?xml version="1.0"?>
<robot name="robo" xmlns:xacro="http://www.ros.org/wiki/xacro"
                   xmlns:gz="http://gazebosim.org/schema">

  <!-- ═══════════════ PROPERTIES ═══════════════ -->
  <xacro:property name="wheel_radius"     value="0.0439222"/>
  <xacro:property name="wheel_width"      value="0.03"/>
  <xacro:property name="wheel_separation" value="0.204108"/>   <!-- Y distance between left & right -->
  <xacro:property name="wheelbase"        value="0.151410"/>   <!-- X distance between front & back -->

  <!-- ═══════════════ BASE FOOTPRINT ═══════════════ -->
  <link name="base_footprint"/>

  <joint name="base_footprint_joint" type="fixed">
    <origin xyz="0 0 ${wheel_radius}" rpy="0 0 0"/>
    <parent link="base_footprint"/>
    <child  link="base_link"/>
  </joint>

  <!-- ═══════════════ BASE LINK ═══════════════ -->
  <link name="base_link">
    <inertial>
      <origin xyz="0 0 0" rpy="0 0 0"/>
      <mass value="2.5"/>
      <inertia ixx="0.03311" iyy="0.019021" izz="0.0495"
               ixy="0" iyz="0" ixz="0"/>
    </inertial>
    <visual>
      <origin xyz="0 0 0.04" rpy="0 0 0"/>
      <geometry><box size="0.20 0.18 0.08"/></geometry>
      <material name="blue"><color rgba="0 0.1 0.6 1"/></material>
    </visual>
    <collision>
      <origin xyz="0 0 0.04" rpy="0 0 0"/>
      <geometry><box size="0.20 0.18 0.08"/></geometry>
    </collision>
  </link>

  <!-- ═══════════════ WHEEL MACRO ═══════════════
       Collision = SPHERE (gz-sim mecanum pattern)
       Friction set via <gazebo reference> block below
  ══════════════════════════════════════════════ -->
  <xacro:macro name="wheel" params="name jx jy fdir1_x fdir1_y">

    <link name="${name}">
      <inertial>
        <origin xyz="0 0 0" rpy="0 0 0"/>
        <mass value="0.789"/>
        <inertia ixx="0.000422" iyy="0.000761" izz="0.000422"
                 ixy="0" iyz="0" ixz="0"/>
      </inertial>
      <visual>
        <origin xyz="0 0 0" rpy="1.5708 0 0"/>
        <geometry><cylinder radius="${wheel_radius}" length="${wheel_width}"/></geometry>
        <material name="white"><color rgba="1 1 1 1"/></material>
      </visual>
      <!-- SPHERE for collision — required for gz-sim mecanum fdir1 to work -->
      <collision>
        <origin xyz="0 0 0" rpy="0 0 0"/>
        <geometry><sphere radius="${wheel_radius}"/></geometry>
      </collision>
    </link>

    <joint name="${name}_joint" type="continuous">
      <origin xyz="${jx} ${jy} 0" rpy="0 0 0"/>
      <parent link="base_link"/>
      <child  link="${name}"/>
      <axis xyz="0 1 0"/>
      <dynamics damping="0.01" friction="0.0"/>
    </joint>

    <!-- Anisotropic friction — gz:expressed_in tells gz-sim the frame for fdir1 -->
    <gazebo reference="${name}">
      <material>Gazebo/White</material>
      <collision>
        <surface>
          <friction>
            <ode>
              <mu>1.5</mu>
              <mu2>0.0</mu2>
              <fdir1 gz:expressed_in="base_footprint">${fdir1_x} ${fdir1_y} 0</fdir1>
            </ode>
          </friction>
        </surface>
      </collision>
    </gazebo>

  </xacro:macro>

  <!-- ═══════════════ WHEEL INSTANCES ═══════════════
       fdir1 encodes the 45° roller angle per wheel:
         front_left  / rear_right  →  1 -1  (rollers at -45°)
         front_right / rear_left   →  1  1  (rollers at +45°)
  ═════════════════════════════════════════════════ -->
  <xacro:wheel name="front_left"
    jx=" ${wheelbase/2}"  jy=" ${wheel_separation/2}"
    fdir1_x="1" fdir1_y="-1"/>

  <xacro:wheel name="front_right"
    jx=" ${wheelbase/2}"  jy="-${wheel_separation/2}"
    fdir1_x="1" fdir1_y="1"/>

  <xacro:wheel name="rear_left"
    jx="-${wheelbase/2}"  jy=" ${wheel_separation/2}"
    fdir1_x="1" fdir1_y="1"/>

  <xacro:wheel name="rear_right"
    jx="-${wheelbase/2}"  jy="-${wheel_separation/2}"
    fdir1_x="1" fdir1_y="-1"/>

  <!-- ═══════════════ LIDAR ═══════════════ -->
  <link name="lidar_link">
    <inertial>
      <origin xyz="0 0 0" rpy="0 0 0"/>
      <mass value="0.2"/>
      <inertia ixx="5.2e-05" iyy="5.2e-05" izz="5.9e-05"
               ixy="0" iyz="0" ixz="0"/>
    </inertial>
    <visual>
      <origin xyz="0 0 0" rpy="0 0 0"/>
      <geometry><cylinder radius="0.04" length="0.04"/></geometry>
      <material name="grey"><color rgba="0.5 0.5 0.5 1"/></material>
    </visual>
    <collision>
      <origin xyz="0 0 0" rpy="0 0 0"/>
      <geometry><cylinder radius="0.04" length="0.04"/></geometry>
    </collision>
  </link>
  <joint name="lidar_joint" type="fixed">
    <origin xyz="0 0 0.10" rpy="0 0 0"/>
    <parent link="base_link"/>
    <child  link="lidar_link"/>
  </joint>

  <!-- ═══════════════ IMU ═══════════════ -->
  <link name="imu_link">
    <inertial>
      <origin xyz="0 0 0" rpy="0 0 0"/>
      <mass value="0.01"/>
      <inertia ixx="1e-6" iyy="1e-6" izz="1e-6"
               ixy="0" iyz="0" ixz="0"/>
    </inertial>
    <visual>
      <geometry><box size="0.02 0.02 0.01"/></geometry>
      <material name="red"><color rgba="0.8 0 0 1"/></material>
    </visual>
    <collision>
      <geometry><box size="0.02 0.02 0.01"/></geometry>
    </collision>
  </link>
  <joint name="imu_joint" type="fixed">
    <origin xyz="0 0 0.05" rpy="0 0 0"/>
    <parent link="base_link"/>
    <child  link="imu_link"/>
  </joint>

  <!-- ═══════════════ GAZEBO PLUGINS ═══════════════ -->
  <gazebo>
    <plugin filename="gz-sim-mecanum-drive-system"
            name="gz::sim::systems::MecanumDrive">
      <front_left_joint>front_left_joint</front_left_joint>
      <front_right_joint>front_right_joint</front_right_joint>
      <back_left_joint>rear_left_joint</back_left_joint>
      <back_right_joint>rear_right_joint</back_right_joint>
      <wheel_separation>${wheel_separation}</wheel_separation>
      <wheelbase>${wheelbase}</wheelbase>
      <wheel_radius>${wheel_radius}</wheel_radius>
      <topic>cmd_vel</topic>
      <odom_topic>odom</odom_topic>
      <tf_topic>tf</tf_topic>
      <frame_id>odom</frame_id>
      <child_frame_id>base_footprint</child_frame_id>
      <odom_publish_frequency>50</odom_publish_frequency>
      <publish_odom>true</publish_odom>
      <publish_odom_tf>true</publish_odom_tf>
      <publish_wheel_tf>false</publish_wheel_tf>
      <min_velocity>-2.0</min_velocity>
      <max_velocity>2.0</max_velocity>
      <min_acceleration>-5.0</min_acceleration>
      <max_acceleration>5.0</max_acceleration>
    </plugin>
  </gazebo>

  <gazebo>
    <plugin filename="gz-sim-joint-state-publisher-system"
            name="gz::sim::systems::JointStatePublisher">
      <joint_name>front_left_joint</joint_name>
      <joint_name>front_right_joint</joint_name>
      <joint_name>rear_left_joint</joint_name>
      <joint_name>rear_right_joint</joint_name>
      <topic>joint_states</topic>
      <update_rate>50</update_rate>
    </plugin>
  </gazebo>

  <!-- 2-D LiDAR sensor -->
  <gazebo reference="lidar_link">
    <material>Gazebo/Grey</material>
    <sensor name="gpu_lidar" type="gpu_lidar">
      <pose>0 0 0 0 0 0</pose>
      <topic>scan</topic>
      <update_rate>10</update_rate>
      <ray>
        <scan>
          <horizontal>
            <samples>360</samples>
            <resolution>1</resolution>
            <min_angle>-3.14159265</min_angle>
            <max_angle> 3.14159265</max_angle>
          </horizontal>
        </scan>
        <range>
          <min>0.15</min>
          <max>12.0</max>
          <resolution>0.01</resolution>
        </range>
        <noise>
          <type>gaussian</type>
          <mean>0.0</mean>
          <stddev>0.01</stddev>
        </noise>
      </ray>
      <always_on>true</always_on>
      <visualize>true</visualize>
      <gz_frame_id>lidar_link</gz_frame_id>
    </sensor>
  </gazebo>

  <!-- IMU sensor -->
  <gazebo reference="imu_link">
    <material>Gazebo/Red</material>
    <sensor name="imu_sensor" type="imu">
      <pose>0 0 0 0 0 0</pose>
      <topic>imu</topic>
      <update_rate>100</update_rate>
      <imu>
        <angular_velocity>
          <x><noise type="gaussian"><mean>0.0</mean><stddev>2e-4</stddev>
            <bias_mean>0.0000075</bias_mean><bias_stddev>0.0000008</bias_stddev></noise></x>
          <y><noise type="gaussian"><mean>0.0</mean><stddev>2e-4</stddev>
            <bias_mean>0.0000075</bias_mean><bias_stddev>0.0000008</bias_stddev></noise></y>
          <z><noise type="gaussian"><mean>0.0</mean><stddev>2e-4</stddev>
            <bias_mean>0.0000075</bias_mean><bias_stddev>0.0000008</bias_stddev></noise></z>
        </angular_velocity>
        <linear_acceleration>
          <x><noise type="gaussian"><mean>0.0</mean><stddev>1.7e-2</stddev>
            <bias_mean>0.1</bias_mean><bias_stddev>0.001</bias_stddev></noise></x>
          <y><noise type="gaussian"><mean>0.0</mean><stddev>1.7e-2</stddev>
            <bias_mean>0.1</bias_mean><bias_stddev>0.001</bias_stddev></noise></y>
          <z><noise type="gaussian"><mean>0.0</mean><stddev>1.7e-2</stddev>
            <bias_mean>0.1</bias_mean><bias_stddev>0.001</bias_stddev></noise></z>
        </linear_acceleration>
      </imu>
      <always_on>true</always_on>
      <gz_frame_id>imu_link</gz_frame_id>
    </sensor>
  </gazebo>

  <gazebo reference="base_link"><material>Gazebo/Blue</material></gazebo>

</robot>
